<?xml version="1.0" encoding="UTF-8"?>
<!-- Generated by org.testng.reporters.JUnitXMLReporter -->
<testsuite hostname="PC-20170725TZYG" name="79BQADR4XV6L8" tests="3" failures="3" timestamp="22 Sep 2017 01:12:15 GMT" time="141.946" errors="0">
  <testcase name="login" time="33.141" classname="cn.crazy.appium.testcases.ZhihuTest">
    <failure type="java.lang.AssertionError" message="login failure">
      <![CDATA[java.lang.AssertionError: login failure
	at cn.crazy.appium.testcases.ZhihuTest.login(ZhihuTest.java:73)
	at java.util.concurrent.FutureTask.run(FutureTask.java:266)
	at java.util.concurrent.ThreadPoolExecutor.runWorker(ThreadPoolExecutor.java:1149)
	at java.util.concurrent.ThreadPoolExecutor$Worker.run(ThreadPoolExecutor.java:624)
	at java.lang.Thread.run(Thread.java:748)
... Removed 17 stack frames]]>
    </failure>
  </testcase> <!-- login -->
  <testcase name="login" time="73.865" classname="cn.crazy.appium.testcases.ZhihuTest">
    <failure type="java.lang.AssertionError" message="login failure">
      <![CDATA[java.lang.AssertionError: login failure
	at cn.crazy.appium.testcases.ZhihuTest.login(ZhihuTest.java:73)
	at java.util.concurrent.FutureTask.run(FutureTask.java:266)
	at java.util.concurrent.ThreadPoolExecutor.runWorker(ThreadPoolExecutor.java:1149)
	at java.util.concurrent.ThreadPoolExecutor$Worker.run(ThreadPoolExecutor.java:624)
	at java.lang.Thread.run(Thread.java:748)
... Removed 17 stack frames]]>
    </failure>
  </testcase> <!-- login -->
  <testcase name="login" time="114.167" classname="cn.crazy.appium.testcases.ZhihuTest">
    <failure type="org.testng.TestNGException" message="
The data provider is trying to pass 1 parameters but the method cn.crazy.appium.testcases.ZhihuTest#login takes 2 and TestNG is unable in inject a suitable object">
      <![CDATA[org.testng.TestNGException: 
The data provider is trying to pass 1 parameters but the method cn.crazy.appium.testcases.ZhihuTest#login takes 2 and TestNG is unable in inject a suitable object
	at java.util.concurrent.FutureTask.run(FutureTask.java:266)
	at java.util.concurrent.ThreadPoolExecutor.runWorker(ThreadPoolExecutor.java:1149)
	at java.util.concurrent.ThreadPoolExecutor$Worker.run(ThreadPoolExecutor.java:624)
	at java.lang.Thread.run(Thread.java:748)
Caused by: java.lang.ArrayIndexOutOfBoundsException: 1
	... 13 more
... Removed 11 stack frames]]>
    </failure>
  </testcase> <!-- login -->
</testsuite> <!-- 79BQADR4XV6L8 -->
